<?xml version="1.0" encoding="utf-8"?>
<!-- =================================================================================== -->
<!-- |    This document was autogenerated by xacro from abb_irb4600s.xacro             | -->
<!-- |    EDITING THIS FILE BY HAND IS NOT RECOMMENDED                                 | -->
<!-- =================================================================================== -->
<robot name="abb_irb4600s">
  <!-- link list -->
  <link name="robLL/base_link">
    <inertial>
      <origin xyz="0.0 0.0 0.0"/>
      <mass value="120.00000"/>
      <inertia ixx="-4.98000" ixy="0.00000" ixz="2.70000" iyy="-5.95200" iyz="0.00000" izz="0.82800"/>
    </inertial>
    <collision name="collision">
      <geometry>
        <mesh filename="package://abb_irb4600s_robots/meshes/collision/base_link.stl"/>
      </geometry>
    </collision>
    <visual name="visual">
      <geometry>
        <mesh filename="package://abb_irb4600s_robots/meshes/visual/base_link.stl"/>
      </geometry>
    </visual>
  </link>
  <link name="robLL/link_1">
    <inertial>
      <origin xyz="0.18000 0.00000 0.50000"/>
      <mass value="120.00000"/>
      <inertia ixx="-4.98000" ixy="0.00000" ixz="2.70000" iyy="-5.95200" iyz="0.00000" izz="0.82800"/>
    </inertial>
    <collision name="collision">
      <geometry>
        <mesh filename="package://abb_irb4600s_robots/meshes/collision/link_1.stl"/>
      </geometry>
    </collision>
    <visual name="visual">
      <geometry>
        <mesh filename="package://abb_irb4600s_robots/meshes/visual/link_1.stl"/>
      </geometry>
    </visual>
  </link>
  <link name="robLL/link_2">
    <inertial>
      <origin xyz="0.94000 0.08000 -0.34000"/>
      <mass value="120.00000"/>
      <inertia ixx="-2.96000" ixy="2.25600" ixz="-9.58800" iyy="-18.72601" iyz="-0.81600" izz="-14.95000"/>
    </inertial>
    <collision name="collision">
      <geometry>
        <mesh filename="package://abb_irb4600s_robots/meshes/collision/link_2.stl"/>
      </geometry>
    </collision>
    <visual name="visual">
      <geometry>
        <mesh filename="package://abb_irb4600s_robots/meshes/visual/link_2.stl"/>
      </geometry>
    </visual>
  </link>
  <link name="robLL/link_3">
    <inertial>
      <origin xyz="0.07000 -0.26600 0.08800"/>
      <mass value="120.00000"/>
      <inertia ixx="1.34500" ixy="0.55860" ixz="0.18480" iyy="4.65068" iyz="-0.70224" izz="2.76032"/>
    </inertial>
    <collision name="collision">
      <geometry>
        <mesh filename="package://abb_irb4600s_robots/meshes/collision/link_3.stl"/>
      </geometry>
    </collision>
    <visual name="visual">
      <geometry>
        <mesh filename="package://abb_irb4600s_robots/meshes/visual/link_3.stl"/>
      </geometry>
    </visual>
  </link>
  <link name="robLL/link_4">
    <inertial>
      <origin xyz="0.00000 0.00000 1.00000"/>
      <mass value="40.00000"/>
      <inertia ixx="-8.00000" ixy="0.00000" ixz="0.00000" iyy="-8.00000" iyz="0.00000" izz="0.48200"/>
    </inertial>
    <collision name="collision">
      <geometry>
        <mesh filename="package://abb_irb4600s_robots/meshes/collision/link_4.stl"/>
      </geometry>
    </collision>
    <visual name="visual">
      <geometry>
        <mesh filename="package://abb_irb4600s_robots/meshes/visual/link_4.stl"/>
      </geometry>
    </visual>
  </link>
  <link name="robLL/link_5">
    <inertial>
      <origin xyz="0.14000 0.00000 0.00000"/>
      <mass value="10.00000"/>
      <inertia ixx="0.04000" ixy="0.00000" ixz="0.00000" iyy="-0.00900" iyz="0.00000" izz="-0.00400"/>
    </inertial>
    <collision name="collision">
      <geometry>
        <mesh filename="package://abb_irb4600s_robots/meshes/collision/link_5.stl"/>
      </geometry>
    </collision>
    <visual name="visual">
      <geometry>
        <mesh filename="package://abb_irb4600s_robots/meshes/visual/link_5.stl"/>
      </geometry>
    </visual>
  </link>
  <link name="robLL/link_6">
    <inertial>
      <origin xyz="0.08100 -0.09100 0.33200"/>
      <mass value="5.00000"/>
      <inertia ixx="-0.29652" ixy="-0.03686" ixz="0.09396" iyy="-0.28792" iyz="-0.10556" izz="-0.04621"/>
    </inertial>
    <collision name="collision">
      <geometry>
        <mesh filename="package://abb_irb4600s_robots/meshes/collision/link_6.stl"/>
      </geometry>
    </collision>
    <visual name="visual">
      <geometry>
        <mesh filename="package://abb_irb4600s_robots/meshes/visual/link_6.stl"/>
      </geometry>
    </visual>
  </link>
  <!-- end of link list -->
  <!-- joint list -->
  <joint name="robLL/joint_1" type="revolute">
    <origin rpy="0 0 0" xyz="0 0 0.495"/>
    <axis xyz="0 0 1"/>
    <parent link="robLL/base_link"/>
    <child link="robLL/link_1"/>
    <!-- (-180 to 180) -->
    <limit effort="100000" lower="-3.14159265359" upper="3.14159265359" velocity="2.618"/>
    <dynamics damping="0.2" friction="0"/>
  </joint>
  <joint name="robLL/joint_2" type="revolute">
    <origin rpy="0 0 0" xyz="0.175 0 0"/>
    <axis xyz="0 1 0"/>
    <parent link="robLL/link_1"/>
    <child link="robLL/link_2"/>
    <!-- (-90 to 150) -->
    <limit effort="100000" lower="-1.57079632679" upper="2.61799387799" velocity="2.618"/>
    <dynamics damping="0.2" friction="0"/>
  </joint>
  <joint name="robLL/joint_3" type="revolute">
    <origin rpy="0 0 0" xyz="0 0 1.095"/>
    <axis xyz="0 1 0"/>
    <parent link="robLL/link_2"/>
    <child link="robLL/link_3"/>
    <!-- (-180 to 75) -->
    <limit effort="100000" lower="-3.14159265359" upper="1.308996939" velocity="2.618"/>
    <dynamics damping="0.2" friction="0"/>
  </joint>
  <joint name="robLL/joint_4" type="revolute">
    <origin rpy="1.57079632679 0 0" xyz="0 0 0.175"/>
    <axis xyz="1 0 0"/>
    <parent link="robLL/link_3"/>
    <child link="robLL/link_4"/>
    <!-- (-400 to 400) -->
    <limit effort="10000" lower="-6.98131700798" upper="6.98131700798" velocity="6.2832"/>
    <dynamics damping="0.2" friction="0"/>
  </joint>
  <joint name="robLL/joint_5" type="revolute">
    <origin rpy="-1.57079632679 0 0" xyz="1.270 0 0"/>
    <axis xyz="0 1 0"/>
    <parent link="robLL/link_4"/>
    <child link="robLL/link_5"/>
    <!-- (-125 to 120) -->
    <limit effort="100000" lower="-2.18166" upper="2.18166156499" velocity="6.2832"/>
    <dynamics damping="0.2" friction="0"/>
  </joint>
  <joint name="robLL/joint_6" type="revolute">
    <origin rpy="0 0 0" xyz="0.135 0 0"/>
    <axis xyz="1 0 0"/>
    <parent link="robLL/link_5"/>
    <child link="robLL/link_6"/>
    <!-- (-400 to 400) -->
    <limit effort="100000" lower="-6.98131700798" upper="6.98131700798" velocity="7.854"/>
    <dynamics damping="0.2" friction="0"/>
  </joint>
  <!-- end of joint list -->
  <!-- ROS-Industrial 'base' frame: base_link to ABB World Coordinates transform -->
  <link name="robLL/base"/>
  <joint name="robLL/base_link-base" type="fixed">
    <origin rpy="0 0 0" xyz="0 0 0"/>
    <parent link="robLL/base_link"/>
    <child link="robLL/base"/>
  </joint>
  <!-- ROS-Industrial 'flange' frame: attachment point for EEF models -->
  <link name="robLL/flange"/>
  <joint name="robLL/joint_6-flange" type="fixed">
    <origin rpy="0 0 0" xyz="0 0 0"/>
    <parent link="robLL/link_6"/>
    <child link="robLL/flange"/>
  </joint>
  <!-- ROS-Industrial 'tool0' frame: all-zeros tool frame -->
  <link name="robLL/tool0"/>
  <joint name="robLL/link_6-tool0" type="fixed">
    <origin rpy="0 1.57079632679 0" xyz="0 0 0"/>
    <parent link="robLL/flange"/>
    <child link="robLL/tool0"/>
  </joint>
  <link name="robLL/irbt4004">
    <visual>
      <geometry>
        <mesh filename="package://abb_irb4600s_robots/meshes/visual/irbt4004.stl"/>
      </geometry>
    </visual>
    <collision>
      <geometry>
        <mesh filename="package://abb_irb4600s_robots/meshes/collision/irbt4004.stl"/>
      </geometry>
    </collision>
  </link>
  <link name="robLL/carriage">
    <visual>
      <geometry>
        <mesh filename="package://abb_irb4600s_robots/meshes/visual/carriage.stl"/>
      </geometry>
    </visual>
    <collision>
      <geometry>
        <mesh filename="package://abb_irb4600s_robots/meshes/collision/carriage.stl"/>
      </geometry>
    </collision>
  </link>
  <joint name="robLL/robot_attachment" type="fixed">
    <parent link="robLL/carriage"/>
    <child link="robLL/base_link"/>
    <origin rpy="0 0 1.57079632679" xyz="0 0 0"/>
  </joint>
  <joint name="robLL/track_carriage" type="prismatic">
    <parent link="robLL/irbt4004"/>
    <child link="robLL/carriage"/>
    <origin rpy="0 0 0" xyz="0 0 0"/>
    <axis xyz="1 0 0"/>
    <limit effort="0" lower="0.0" upper="3.9" velocity="1.0"/>
  </joint>
  <!-- link list -->
  <link name="robRR/base_link">
    <inertial>
      <origin xyz="0.0 0.0 0.0"/>
      <mass value="120.00000"/>
      <inertia ixx="-4.98000" ixy="0.00000" ixz="2.70000" iyy="-5.95200" iyz="0.00000" izz="0.82800"/>
    </inertial>
    <collision name="collision">
      <geometry>
        <mesh filename="package://abb_irb4600s_robots/meshes/collision/base_link.stl"/>
      </geometry>
    </collision>
    <visual name="visual">
      <geometry>
        <mesh filename="package://abb_irb4600s_robots/meshes/visual/base_link.stl"/>
      </geometry>
    </visual>
  </link>
  <link name="robRR/link_1">
    <inertial>
      <origin xyz="0.18000 0.00000 0.50000"/>
      <mass value="120.00000"/>
      <inertia ixx="-4.98000" ixy="0.00000" ixz="2.70000" iyy="-5.95200" iyz="0.00000" izz="0.82800"/>
    </inertial>
    <collision name="collision">
      <geometry>
        <mesh filename="package://abb_irb4600s_robots/meshes/collision/link_1.stl"/>
      </geometry>
    </collision>
    <visual name="visual">
      <geometry>
        <mesh filename="package://abb_irb4600s_robots/meshes/visual/link_1.stl"/>
      </geometry>
    </visual>
  </link>
  <link name="robRR/link_2">
    <inertial>
      <origin xyz="0.94000 0.08000 -0.34000"/>
      <mass value="120.00000"/>
      <inertia ixx="-2.96000" ixy="2.25600" ixz="-9.58800" iyy="-18.72601" iyz="-0.81600" izz="-14.95000"/>
    </inertial>
    <collision name="collision">
      <geometry>
        <mesh filename="package://abb_irb4600s_robots/meshes/collision/link_2.stl"/>
      </geometry>
    </collision>
    <visual name="visual">
      <geometry>
        <mesh filename="package://abb_irb4600s_robots/meshes/visual/link_2.stl"/>
      </geometry>
    </visual>
  </link>
  <link name="robRR/link_3">
    <inertial>
      <origin xyz="0.07000 -0.26600 0.08800"/>
      <mass value="120.00000"/>
      <inertia ixx="1.34500" ixy="0.55860" ixz="0.18480" iyy="4.65068" iyz="-0.70224" izz="2.76032"/>
    </inertial>
    <collision name="collision">
      <geometry>
        <mesh filename="package://abb_irb4600s_robots/meshes/collision/link_3.stl"/>
      </geometry>
    </collision>
    <visual name="visual">
      <geometry>
        <mesh filename="package://abb_irb4600s_robots/meshes/visual/link_3.stl"/>
      </geometry>
    </visual>
  </link>
  <link name="robRR/link_4">
    <inertial>
      <origin xyz="0.00000 0.00000 1.00000"/>
      <mass value="40.00000"/>
      <inertia ixx="-8.00000" ixy="0.00000" ixz="0.00000" iyy="-8.00000" iyz="0.00000" izz="0.48200"/>
    </inertial>
    <collision name="collision">
      <geometry>
        <mesh filename="package://abb_irb4600s_robots/meshes/collision/link_4.stl"/>
      </geometry>
    </collision>
    <visual name="visual">
      <geometry>
        <mesh filename="package://abb_irb4600s_robots/meshes/visual/link_4.stl"/>
      </geometry>
    </visual>
  </link>
  <link name="robRR/link_5">
    <inertial>
      <origin xyz="0.14000 0.00000 0.00000"/>
      <mass value="10.00000"/>
      <inertia ixx="0.04000" ixy="0.00000" ixz="0.00000" iyy="-0.00900" iyz="0.00000" izz="-0.00400"/>
    </inertial>
    <collision name="collision">
      <geometry>
        <mesh filename="package://abb_irb4600s_robots/meshes/collision/link_5.stl"/>
      </geometry>
    </collision>
    <visual name="visual">
      <geometry>
        <mesh filename="package://abb_irb4600s_robots/meshes/visual/link_5.stl"/>
      </geometry>
    </visual>
  </link>
  <link name="robRR/link_6">
    <inertial>
      <origin xyz="0.08100 -0.09100 0.33200"/>
      <mass value="5.00000"/>
      <inertia ixx="-0.29652" ixy="-0.03686" ixz="0.09396" iyy="-0.28792" iyz="-0.10556" izz="-0.04621"/>
    </inertial>
    <collision name="collision">
      <geometry>
        <mesh filename="package://abb_irb4600s_robots/meshes/collision/link_6.stl"/>
      </geometry>
    </collision>
    <visual name="visual">
      <geometry>
        <mesh filename="package://abb_irb4600s_robots/meshes/visual/link_6.stl"/>
      </geometry>
    </visual>
  </link>
  <!-- end of link list -->
  <!-- joint list -->
  <joint name="robRR/joint_1" type="revolute">
    <origin rpy="0 0 0" xyz="0 0 0.495"/>
    <axis xyz="0 0 1"/>
    <parent link="robRR/base_link"/>
    <child link="robRR/link_1"/>
    <!-- (-180 to 180) -->
    <limit effort="100000" lower="-3.14159265359" upper="3.14159265359" velocity="2.618"/>
    <dynamics damping="0.2" friction="0"/>
  </joint>
  <joint name="robRR/joint_2" type="revolute">
    <origin rpy="0 0 0" xyz="0.175 0 0"/>
    <axis xyz="0 1 0"/>
    <parent link="robRR/link_1"/>
    <child link="robRR/link_2"/>
    <!-- (-90 to 150) -->
    <limit effort="100000" lower="-1.57079632679" upper="2.61799387799" velocity="2.618"/>
    <dynamics damping="0.2" friction="0"/>
  </joint>
  <joint name="robRR/joint_3" type="revolute">
    <origin rpy="0 0 0" xyz="0 0 1.095"/>
    <axis xyz="0 1 0"/>
    <parent link="robRR/link_2"/>
    <child link="robRR/link_3"/>
    <!-- (-180 to 75) -->
    <limit effort="100000" lower="-3.14159265359" upper="1.308996939" velocity="2.618"/>
    <dynamics damping="0.2" friction="0"/>
  </joint>
  <joint name="robRR/joint_4" type="revolute">
    <origin rpy="1.57079632679 0 0" xyz="0 0 0.175"/>
    <axis xyz="1 0 0"/>
    <parent link="robRR/link_3"/>
    <child link="robRR/link_4"/>
    <!-- (-400 to 400) -->
    <limit effort="10000" lower="-6.98131700798" upper="6.98131700798" velocity="6.2832"/>
    <dynamics damping="0.2" friction="0"/>
  </joint>
  <joint name="robRR/joint_5" type="revolute">
    <origin rpy="-1.57079632679 0 0" xyz="1.270 0 0"/>
    <axis xyz="0 1 0"/>
    <parent link="robRR/link_4"/>
    <child link="robRR/link_5"/>
    <!-- (-125 to 120) -->
    <limit effort="100000" lower="-2.18166" upper="2.18166156499" velocity="6.2832"/>
    <dynamics damping="0.2" friction="0"/>
  </joint>
  <joint name="robRR/joint_6" type="revolute">
    <origin rpy="0 0 0" xyz="0.135 0 0"/>
    <axis xyz="1 0 0"/>
    <parent link="robRR/link_5"/>
    <child link="robRR/link_6"/>
    <!-- (-400 to 400) -->
    <limit effort="100000" lower="-6.98131700798" upper="6.98131700798" velocity="7.854"/>
    <dynamics damping="0.2" friction="0"/>
  </joint>
  <!-- end of joint list -->
  <!-- ROS-Industrial 'base' frame: base_link to ABB World Coordinates transform -->
  <link name="robRR/base"/>
  <joint name="robRR/base_link-base" type="fixed">
    <origin rpy="0 0 0" xyz="0 0 0"/>
    <parent link="robRR/base_link"/>
    <child link="robRR/base"/>
  </joint>
  <!-- ROS-Industrial 'flange' frame: attachment point for EEF models -->
  <link name="robRR/flange"/>
  <joint name="robRR/joint_6-flange" type="fixed">
    <origin rpy="0 0 0" xyz="0 0 0"/>
    <parent link="robRR/link_6"/>
    <child link="robRR/flange"/>
  </joint>
  <!-- ROS-Industrial 'tool0' frame: all-zeros tool frame -->
  <link name="robRR/tool0"/>
  <joint name="robRR/link_6-tool0" type="fixed">
    <origin rpy="0 1.57079632679 0" xyz="0 0 0"/>
    <parent link="robRR/flange"/>
    <child link="robRR/tool0"/>
  </joint>
  <link name="robRR/irbt4004">
    <visual>
      <geometry>
        <mesh filename="package://abb_irb4600s_robots/meshes/visual/irbt4004.stl"/>
      </geometry>
    </visual>
    <collision>
      <geometry>
        <mesh filename="package://abb_irb4600s_robots/meshes/collision/irbt4004.stl"/>
      </geometry>
    </collision>
  </link>
  <link name="robRR/carriage">
    <visual>
      <geometry>
        <mesh filename="package://abb_irb4600s_robots/meshes/visual/carriage.stl"/>
      </geometry>
    </visual>
    <collision>
      <geometry>
        <mesh filename="package://abb_irb4600s_robots/meshes/collision/carriage.stl"/>
      </geometry>
    </collision>
  </link>
  <joint name="robRR/robot_attachment" type="fixed">
    <parent link="robRR/carriage"/>
    <child link="robRR/base_link"/>
    <origin rpy="0 0 1.57079632679" xyz="0 0 0"/>
  </joint>
  <joint name="robRR/track_carriage" type="prismatic">
    <parent link="robRR/irbt4004"/>
    <child link="robRR/carriage"/>
    <origin rpy="0 0 0" xyz="0 0 0"/>
    <axis xyz="1 0 0"/>
    <limit effort="0" lower="0.0" upper="3.9" velocity="1.0"/>
  </joint>
  <link name="world"/>
  <joint name="robRR/origin" type="fixed">
    <parent link="world"/>
    <child link="robRR/irbt4004"/>
    <origin rpy="0.0 0.0 0.0" xyz="0.0 0.0 0.0"/>
  </joint>
  <joint name="robLL/origin" type="fixed">
    <parent link="world"/>
    <child link="robLL/irbt4004"/>
    <origin rpy="0.0 0.0 3.14159265359" xyz="3.6993 3.4510 0.0316"/>
  </joint>
</robot>
